Workbook

Sheet 2026 EOM and Scores
I1: CALCULATIONS TEST | S1: EOM TOPIC QUIZ | AC1: EOM PRECEPTOR OSCE
B2: Intern Name | C2: Branch | D2: Region | E2: Pathway | F2: Colour | G2: 1st Aid | H2: Vac | I2: Jan | J2: Feb | K2: Mar | L2: Apr | M2: May | N2: Jun | O2: Jul | P2: Aug | Q2: Sep | S2: Feb | T2: Mar | U2: Apr | V2: May. | W2: Jun | X2: Jul | Y2: Aug | Z2: Sep | AA2: EOY | AB2: ---- | AC2: Feb. | AD2: Mar. | AE2: Apr. | AF2: May. | AG2: Jun. | AH2: Jul. | AI2: Aug. | AJ2: Sep. | AK2: Oct
B3: Abhishek Sharma | C3: Centre Place | D3: =VLOOKUP('2026 EOM and Scores'!$C3,'[1]Lists (Ignore)'!$N:$O,2,FALSE) -> #N/A | E3: NonREQR | F3: #REF! | G3: Yes | H3: Pending | I3: Not Done | J3: Not Done | K3: 11 | L3: 12 | M3: N/A | N3: N/A | O3: N/A | P3: N/A | Q3: N/A | S3: Not Done | T3: 14 | U3: 14 | AC3: 1/3 | AD3: 1/3
B4: Alyssa Andres | C4: Blenheim Square | D4: =VLOOKUP('2026 EOM and Scores'!$C4,'[1]Lists (Ignore)'!$N:$O,2,FALSE) -> #N/A | E4: NonREQR | F4: #REF! | I4: Not Done | J4: Not Done | K4: 7 | L4: N/A | M4: N/A | N4: N/A | O4: N/A | P4: N/A | Q4: N/A | S4: Not Done | T4: 8 | AC4: 3/3 | AD4: 2/3
B5: Amalnath Sadanandan | C5: Springlands | D5: =VLOOKUP('2026 EOM and Scores'!$C5,'[1]Lists (Ignore)'!$N:$O,2,FALSE) -> #N/A | E5: NonREQR | F5: #REF! | G5: No | H5: Pending | I5: 11 | J5: 11 | K5: 12 | L5: N/A | M5: N/A | N5: N/A | O5: N/A | P5: N/A | Q5: N/A | S5: 25 | T5: 13 | AC5: 3/3 | AD5: 2/3
B6: Amrutha Chelath | C6: Ormiston | D6: =VLOOKUP('2026 EOM and Scores'!$C6,'[1]Lists (Ignore)'!$N:$O,2,FALSE) -> #N/A | E6: NonREQR | F6: #REF! | G6: No | H6: Pending | I6: Not Done | J6: 12 | K6: Not Done | S6: 25 | T6: 14 | AC6: 3/3 | AD6: 3/3
B7: Angel Paul | C7: Bethlehem | D7: =VLOOKUP('2026 EOM and Scores'!$C7,'[1]Lists (Ignore)'!$N:$O,2,FALSE) -> #N/A | E7: NonREQR | F7: #REF! | G7: Yes | H7: Pending | I7: 9 | J7: Not Done | K7: Not Done | S7: Not Done | T7: Not Done | AC7: 1/3 | AD7: 1/3
B8: Ann (Lorieall) Sureta | C8: Fraser Cove | D8: =VLOOKUP('2026 EOM and Scores'!$C8,'[1]Lists (Ignore)'!$N:$O,2,FALSE) -> #N/A | E8: NonREQR | F8: #REF! | G8: No | H8: Pending | I8: 8 | J8: 9 | K8: Not Done | S8: 25 | T8: Not Done | AC8: 3/3 | AD8: 3/3
B9: Annissa Izham | C9: Lambton Quay | D9: =VLOOKUP('2026 EOM and Scores'!$C9,'[1]Lists (Ignore)'!$N:$O,2,FALSE) -> #N/A | E9: Otago | F9: #REF! | G9: Yes | H9: Pending | I9: 10 | J9: Not Done | K9: Not Done | L9: N/A | M9: N/A | N9: N/A | O9: N/A | P9: N/A | Q9: N/A | S9: Not Done | T9: Not Done | AC9: 2/3 | AD9: 1/3
B10: Anumol Paulose | C10: Bethlehem | D10: =VLOOKUP('2026 EOM and Scores'!$C10,'[1]Lists (Ignore)'!$N:$O,2,FALSE) -> #N/A | E10: NonREQR | F10: #REF! | G10: Yes | H10: Pending | I10: 9 | J10: Not Done | K10: Not Done | S10: Not Done | T10: Not Done | AC10: 1/3 | AD10: 1/3
B11: Ayesha Tabinda | C11: Taupo | D11: =VLOOKUP('2026 EOM and Scores'!$C11,'[1]Lists (Ignore)'!$N:$O,2,FALSE) -> #N/A | E11: NonREQR | F11: #REF! | G11: Pending | H11: No | I11: 6 | J11: 11 | K11: 12 | S11: 10 | T11: 7 | AC11: 1/3 | AD11: 1/3
B12: Aziza Shawudun | C12: Auckland - Lower Queen St | D12: =VLOOKUP('2026 EOM and Scores'!$C12,'[1]Lists (Ignore)'!$N:$O,2,FALSE) -> #N/A | E12: Auckland | F12: #REF! | G12: No | H12: Pending | I12: 7 | J12: 7 | K12: 7 | S12: 24 | T12: 13 | AC12: 0/3 | AD12: 0/3
B13: Chinwe Stella Melifonwu | C13: The Valley | D13: =VLOOKUP('2026 EOM and Scores'!$C13,'[1]Lists (Ignore)'!$N:$O,2,FALSE) -> #N/A | E13: NonREQR | F13: #REF! | G13: No | H13: No | I13: Not Done | J13: 8 | K13: 8 | S13: 17 | T13: 8 | AC13: 3/3 | AD13: 3/3
B14: Crystal (Jooeun) Yi | C14: The Palms | D14: =VLOOKUP('2026 EOM and Scores'!$C14,'[1]Lists (Ignore)'!$N:$O,2,FALSE) -> #N/A | E14: Otago | F14: #REF! | I14: Not Done | J14: 9 | K14: Not Done | L14: N/A | M14: N/A | N14: N/A | O14: N/A | P14: N/A | Q14: N/A | S14: 18 | T14: Not Done | AC14: 0/3 | AD14: 0/3
B15: Ella (Jinghan) Wang | C15: The Palms | D15: =VLOOKUP('2026 EOM and Scores'!$C15,'[1]Lists (Ignore)'!$N:$O,2,FALSE) -> #N/A | E15: Otago | F15: #REF! | I15: Not Done | J15: Not Done | K15: Not Done | L15: N/A | M15: N/A | N15: N/A | O15: N/A | P15: N/A | Q15: N/A | S15: Not Done | T15: Not Done | AC15: 0/3 | AD15: 0/3
B16: Ehsan Etemad Kasaeian | C16: Warkworth | D16: =VLOOKUP('2026 EOM and Scores'!$C16,'[1]Lists (Ignore)'!$N:$O,2,FALSE) -> #N/A | E16: NonREQR | F16: ='[2]Intern Progress'!I16 -> #REF! | I16: Not Done | J16: Not Done | K16: Not Done | S16: Not Done | T16: Not Done | AC16: 0/3 | AD16: 0/3
B17: Farhana Naureen Anwar | C17: Taupo | D17: =VLOOKUP('2026 EOM and Scores'!$C17,'[1]Lists (Ignore)'!$N:$O,2,FALSE) -> #N/A | E17: NonREQR | F17: #REF! | G17: No | H17: No | I17: 4 | J17: Not Done | K17: Not Done | L17: N/A | M17: N/A | N17: N/A | O17: N/A | P17: N/A | Q17: N/A | S17: Not Done | T17: Not Done | AC17: 0/3 | AD17: 0/3
B18: Frances Diana Encarnacion | C18: Henderson | D18: =VLOOKUP('2026 EOM and Scores'!$C18,'[1]Lists (Ignore)'!$N:$O,2,FALSE) -> #N/A | E18: NonREQR | F18: #REF! | G18: Yes | H18: No | I18: 4 | J18: 3 | K18: Not Done | S18: 23 | T18: 9 | AC18: 3/3 | AD18: 3/3
B19: Fylgia Romero | C19: South City Shopping Centre | D19: =VLOOKUP('2026 EOM and Scores'!$C19,'[1]Lists (Ignore)'!$N:$O,2,FALSE) -> #N/A | E19: Otago | F19: #REF! | I19: Not Done | J19: 11 | K19: Not Done | L19: N/A | M19: N/A | N19: N/A | O19: N/A | P19: N/A | Q19: N/A | S19: 19 | T19: Not Done | AC19: 2/3 | AD19: 1/3 | AE19: 2/3
B20: Greeshma Raj | C20: South City Shopping Centre | D20: =VLOOKUP('2026 EOM and Scores'!$C20,'[1]Lists (Ignore)'!$N:$O,2,FALSE) -> #N/A | E20: NonREQR | F20: #REF! | I20: Not Done | J20: Not Done | K20: Not Done | S20: Not Done | T20: Not Done | AC20: 0/3 | AD20: 0/3
B21: Gyan (Roger) Ilarde Lumo | C21: Centre Place | D21: =VLOOKUP('2026 EOM and Scores'!$C21,'[1]Lists (Ignore)'!$N:$O,2,FALSE) -> #N/A | E21: Otago | F21: #REF! | G21: Pending | H21: Pending | I21: 7 | J21: Not Done | K21: 7 | L21: N/A | M21: N/A | N21: N/A | O21: N/A | P21: N/A | Q21: N/A | S21: Not Done | T21: 13 | AC21: 3/3 | AD21: 3/3
B22: Hana Nazim | C22: Hunters Plaza | D22: =VLOOKUP('2026 EOM and Scores'!$C22,'[1]Lists (Ignore)'!$N:$O,2,FALSE) -> #N/A | E22: NonREQR | F22: #REF! | G22: No | H22: Pending | I22: 9 | J22: 10 | K22: Not Done | L22: N/A | M22: N/A | N22: N/A | O22: N/A | P22: N/A | Q22: N/A | S22: 23 | T22: Not Done | AC22: 3/3 | AD22: 3/3
B23: Hanna Simon | C23: Okara Park | D23: =VLOOKUP('2026 EOM and Scores'!$C23,'[1]Lists (Ignore)'!$N:$O,2,FALSE) -> #N/A | E23: NonREQR | F23: #REF! | G23: No | H23: Pending | I23: 10 | J23: 9 | K23: Not Done | S23: 23 | T23: Not Done | AC23: 3/3 | AD23: 3/3
B24: Hardik Ahuja | C24: Papanui | D24: =VLOOKUP('2026 EOM and Scores'!$C24,'[1]Lists (Ignore)'!$N:$O,2,FALSE) -> #N/A | E24: NonREQR | F24: #REF! | I24: Not Done | J24: Not Done | K24: Not Done | S24: Not Done | T24: Not Done | AC24: 0/3 | AD24: 0/3
B25: Hatem | C25: Bayfair | D25: =VLOOKUP('2026 EOM and Scores'!$C25,'[1]Lists (Ignore)'!$N:$O,2,FALSE) -> #N/A | E25: NonREQR | F25: #REF! | S25: Not Done | T25: Not Done | AC25: 0/3 | AD25: 0/3
B26: Howard Liu | C26: Rolleston | D26: =VLOOKUP('2026 EOM and Scores'!$C26,'[1]Lists (Ignore)'!$N:$O,2,FALSE) -> #N/A | E26: Otago | F26: #REF! | I26: Not Done | J26: 9 | K26: Not Done | L26: N/A | M26: N/A | N26: N/A | O26: N/A | P26: N/A | Q26: N/A | S26: 23 | T26: Not Done | AC26: 0/3 | AD26: 0/3
B27: Janet Jomon | C27: Fraser Cove | D27: =VLOOKUP('2026 EOM and Scores'!$C27,'[1]Lists (Ignore)'!$N:$O,2,FALSE) -> #N/A | E27: NonREQR | F27: #REF! | G27: Yes | H27: Pending | I27: 9 | J27: Not Done | K27: Not Done | S27: Not Done | T27: Not Done | AC27: 0/3 | AD27: 0/3
B28: Jasmin Jomon | C28: LynnMall | D28: =VLOOKUP('2026 EOM and Scores'!$C28,'[1]Lists (Ignore)'!$N:$O,2,FALSE) -> #N/A | E28: NonREQR | F28: #REF! | G28: No | H28: Pending | I28: 7 | J28: Not Done | K28: 7 | L28: N/A | M28: N/A | N28: N/A | O28: N/A | P28: N/A | Q28: N/A | S28: Not Done | T28: 13 | AC28: 3/3 | AD28: 1/3 | AE28: 1/3
B29: Jay (Zhijian) Wang | C29: Glenfield Mall | D29: =VLOOKUP('2026 EOM and Scores'!$C29,'[1]Lists (Ignore)'!$N:$O,2,FALSE) -> #N/A | E29: Auckland | F29: #REF! | G29: No | H29: Pending | I29: Not Done | J29: 11 | K29: Not Done | L29: N/A | M29: N/A | N29: N/A | O29: N/A | P29: N/A | Q29: N/A | S29: 19 | T29: Not Done | AC29: 1/3 | AD29: 0/3
B30: Jenny (Zhixin) Yan | C30: Chartwell | D30: =VLOOKUP('2026 EOM and Scores'!$C30,'[1]Lists (Ignore)'!$N:$O,2,FALSE) -> #N/A | E30: Auckland | F30: #REF! | G30: Yes | H30: Pending | I30: Not Done | J30: 10 | K30: Not Done | L30: N/A | M30: N/A | N30: N/A | O30: N/A | P30: N/A | Q30: N/A | S30: 18 | T30: Not Done | AC30: 0/3 | AD30: 0/3
B31: Jessie (Jiyun) Jung | C31: Wairau Valley | D31: =VLOOKUP('2026 EOM and Scores'!$C31,'[1]Lists (Ignore)'!$N:$O,2,FALSE) -> #N/A | E31: Auckland | F31: #REF! | G31: No | H31: Pending | I31: Not Done | J31: Not Done | K31: Not Done | S31: Not Done | T31: Not Done | AC31: 0/3 | AD31: 0/3
B32: Ji Hee Jeong | C32: Sylvia Park | D32: =VLOOKUP('2026 EOM and Scores'!$C32,'[1]Lists (Ignore)'!$N:$O,2,FALSE) -> #N/A | E32: Auckland | F32: #REF! | G32: Yes | H32: Pending | I32: Not Done | J32: 12 | K32: Not Done | L32: N/A | M32: N/A | N32: N/A | O32: N/A | P32: N/A | Q32: N/A | S32: 26 | T32: 14 | AC32: 3/3 | AD32: 3/3
B33: Joanne Cao | C33: Botany | D33: =VLOOKUP('2026 EOM and Scores'!$C33,'[1]Lists (Ignore)'!$N:$O,2,FALSE) -> #N/A | E33: Auckland | F33: #REF! | G33: Yes | H33: Pending | I33: 11 | J33: 10 | K33: 0 | L33: N/A | M33: N/A | N33: N/A | O33: N/A | P33: N/A | Q33: N/A | S33: 18 | T33: 10 | AC33: 1/3 | AD33: 3/3
B34: Kamran Ghnbari | C34: Rotorua | D34: =VLOOKUP('2026 EOM and Scores'!$C34,'[1]Lists (Ignore)'!$N:$O,2,FALSE) -> #N/A | E34: NonREQR | F34: #REF! | G34: No | H34: Pending | I34: Not Done | J34: Not Done | K34: Not Done | L34: N/A | M34: N/A | N34: N/A | O34: N/A | P34: N/A | Q34: N/A | S34: Not Done | T34: Not Done | AC34: 0/3 | AD34: 0/3
B35: Kathleen Gomez | C35: Sylvia Park | D35: =VLOOKUP('2026 EOM and Scores'!$C35,'[1]Lists (Ignore)'!$N:$O,2,FALSE) -> #N/A | E35: NonREQR | F35: #REF! | G35: Yes | H35: Pending | I35: 11 | J35: Not Done | K35: Not Done | S35: Not Done | T35: Not Done | AC35: 2/3 | AD35: 1/3
B36: Kisal Lewanjith Bogahakumbura Bogahakumbure | C36: The Valley | D36: =VLOOKUP('2026 EOM and Scores'!$C36,'[1]Lists (Ignore)'!$N:$O,2,FALSE) -> #N/A | E36: NonREQR | F36: #REF! | G36: No | H36: Pending | I36: Not Done | J36: Not Done | K36: Not Done | S36: Not Done | T36: Not Done | AC36: 3/3 | AD36: 3/3
B37: Laurence Richard Gaboy | C37: The Zone | D37: =VLOOKUP('2026 EOM and Scores'!$C37,'[1]Lists (Ignore)'!$N:$O,2,FALSE) -> #N/A | E37: NonREQR | F37: #REF! | G37: No | H37: No | I37: 9 | J37: 9 | K37: Not Done | S37: 21 | T37: Not Done | AC37: 1/3 | AD37: 1/3 | AE37: 1/3
B38: Leah Bunales | C38: Botany Town Centre | D38: =VLOOKUP('2026 EOM and Scores'!$C38,'[1]Lists (Ignore)'!$N:$O,2,FALSE) -> #N/A | E38: NonREQR | F38: #REF! | G38: No | H38: Pending | I38: 10 | J38: 9 | K38: Not Done | L38: N/A | M38: N/A | N38: N/A | O38: N/A | P38: N/A | Q38: N/A | S38: 22 | T38: 12 | AC38: 2/3 | AD38: 3/3
B39: Marvelous (Moradeke) Adesina | C39: The Zone | D39: =VLOOKUP('2026 EOM and Scores'!$C39,'[1]Lists (Ignore)'!$N:$O,2,FALSE) -> #N/A | E39: Auckland | F39: #REF! | G39: Yes | H39: Pending | I39: 9 | J39: 11 | K39: 11 | S39: 25 | T39: 14 | AC39: 1/3 | AD39: 1/3 | AE39: 1/3
B40: Michael Mories Hanna | C40: Bethlehem | D40: =VLOOKUP('2026 EOM and Scores'!$C40,'[1]Lists (Ignore)'!$N:$O,2,FALSE) -> #N/A | E40: NonREQR | F40: #REF! | G40: No | H40: Pending | I40: Not Done | J40: 10 | K40: Not Done | L40: N/A | M40: N/A | N40: N/A | O40: N/A | P40: N/A | Q40: N/A | S40: 21 | T40: 12 | AC40: 1/3 | AD40: 1/3
...

Sheet 2025 EOM Declarations
B2: Auckland | C2: Branch | D2: Mock | E2: Feb | F2: Mar | G2: Apr | H2: May | I2: Jun | J2: Jul | K2: Aug | L2: Sep
A3: 1 | B3: Abdelaziz Adjali | C3: Milford | D3: No | E3: Yes | F3: Yes | G3: Yes | H3: No | I3: No
A4: 2 | B4: Aidhal Varghese | C4: Albany | D4: No | E4: No | F4: No | G4: No | H4: Yes | I4: Yes
A5: 3 | B5: Akshayaa Sribaskaran | C5: Henderson | D5: No | E5: No | F5: No | G5: No | H5: No | I5: No
A6: 4 | B6: Alexander Almazar | C6: Sylvia Park | D6: Yes | E6: Yes | F6: Yes | G6: Yes | H6: Yes | I6: Yes
A7: 5 | B7: Amisha Prasad | C7: LynnMall | D7: Yes | E7: Yes | F7: Yes | G7: Yes | H7: Yes | I7: Yes
A8: 6 | B8: Dijo Dias | C8: Botany | D8: No | E8: Yes | F8: Yes | G8: Yes | H8: Yes | I8: No
A9: 7 | B9: Elizabeth Victoria Lowe | C9: Lower Queen St | D9: No | E9: Yes | F9: Yes | G9: Yes | H9: Yes | I9: No
A10: 8 | B10: Hanna Teklehaimanot | C10: LynnMall | D10: No | E10: Yes | F10: No | G10: No | H10: Yes | I10: Yes
A11: 9 | B11: Hina Saeed | C11: Airport SC | D11: No | E11: No | F11: No | G11: No | H11: Yes | I11: No
A12: 10 | B12: Jordon Long Lay | C12: Newmarket | D12: No | E12: Yes | F12: Yes | G12: Yes | H12: Yes | I12: (2/3)
A13: 11 | B13: Kalpani Siriwardane | C13: The Zone | D13: No | E13: No | F13: No | G13: No | H13: No | I13: No
A14: 12 | B14: Lucas Lin | C14: Silverdale | D14: No | E14: Yes | F14: Yes | G14: Yes | H14: Yes | I14: No
... A29: 27 | B29: Yi Heng Chong | C29: Albany | D29: No | E29: No | F29: No | G29: No | H29: Yes | I29: Yes
B30: Total | D30: =(COUNTIF('2025 EOM Declarations'!$D$3:$D$29,"Yes")) -> 2 | E30: =(COUNTIF('2025 EOM Declarations'!$E$3:$E$29,"Yes")/27) -> 0.59259259 | F30: =(COUNTIF('2025 EOM Declarations'!$F$3:$F$29,"Yes")/27) -> 0.44444444 | G30: =(COUNTIF('2025 EOM Declarations'!$G$3:$G$29,"Yes")/27) -> 0.40740741 | H30: =(COUNTIF('2025 EOM Declarations'!$H$3:$H$29,"Yes")/27) -> 0.51851852 | I30: =(COUNTIF('2025 EOM Declarations'!$I$3:$I$29,"Yes")/27) -> 0.18518519 | J30: =(COUNTIF('2025 EOM Declarations'!$J$3:$J$29,"Yes")/27) -> 0 | K30: =(COUNTIF('2025 EOM Declarations'!$K$3:$K$29,"Yes")/27) -> 0 | L30: =(COUNTIF('2025 EOM Declarations'!$L$3:$L$29,"Yes")/27) -> 0
B34: Regional | C34: Branch | D34: Mock | E34: Feb | F34: Mar | G34: Apr | H34: May | I34: Jun | J34: Jul | K34: Aug | L34: Sep
A35: 1 | B35: Aaron Loh | C35: South City | D35: No | E35: No | F35: No | G35: No | H35: No | I35: No
A36: 2 | B36: Andrea Po | C36: South City | D36: No | E36: No | F36: No | G36: No | H36: No | I36: No
A37: 3 | B37: Anjitha Mathew | C37: Papanui | D37: No | E37: Yes | F37: Yes | G37: Yes | H37: Yes | I37: No
A38: 4 | B38: Bianca Shan | C38: South City | D38: No | E38: No | F38: No | G38: Yes | H38: No | I38: No
A39: 5 | B39: Farisha Hussein | C39: Meridian Mall | D39: No | E39: Yes | F39: No | G39: Yes | H39: Yes | I39: No
A40: 6 | B40: Gopika Kumar | C40: Kilbirnie | D40: No | E40: Yes | F40: Yes | G40: Yes | H40: Yes | I40: No
A41: 7 | B41: Islam Fatouh | C41: Springlands | D41: No | E41: Yes | F41: Yes | G41: No | H41: No | I41: No
A42: 8 | B42: Jackson Whitmore | C42: The Valley | D42: Yes | E42: Yes | F42: Yes | G42: Yes | H42: Yes | I42: Yes
A43: 9 | B43: Jannylene Chua | C43: Papanui | D43: No | E43: No | F43: No | G43: No | H43: No | I43: No
A44: 10 | B44: Josephine Go | C44: Bayfair | D44: Yes | E44: Yes | F44: Yes | G44: Yes | H44: Yes | I44: Yes
A45: 11 | B45: Juliet Chinelo | C45: Whanganui | D45: No | E45: Yes | F45: Yes | G45: No | H45: No | I45: No
A46: 12 | B46: Kirankumar Adepu | C46: Porirua | D46: No | E46: No | F46: Yes | G46: No | H46: No | I46: Yes
... A58: 24 | B58: Vishnu Palakkal | C58: The Valley | D58: Yes | E58: Yes | F58: Yes | G58: Yes | H58: Yes | I58: Yes
B59: Total | D59: =(COUNTIF('2025 EOM Declarations'!$D$35:$D$58,"Yes")) -> 4 | E59: =(COUNTIF('2025 EOM Declarations'!$E$35:$E$58,"Yes")/24) -> 0.625 | F59: =(COUNTIF('2025 EOM Declarations'!$F$35:$F$58,"Yes")/24) -> 0.5 | G59: =(COUNTIF('2025 EOM Declarations'!$G$35:$G$58,"Yes")/24) -> 0.45833333 | H59: =(COUNTIF('2025 EOM Declarations'!$H$35:$H$58,"Yes")/24) -> 0.33333333 | I59: =(COUNTIF('2025 EOM Declarations'!$I$35:$I$58,"Yes")/24) -> 0.20833333 | J59: =(COUNTIF('2025 EOM Declarations'!$J$35:$J$58,"Yes")/24) -> 0 | K59: =(COUNTIF('2025 EOM Declarations'!$K$35:$K$58,"Yes")/24) -> 0 | L59: =(COUNTIF('2025 EOM Declarations'!$L$35:$L$58,"Yes")/24) -> 0

Sheet May Workshop Allocations
B2: Auckland | H2: Online
B3: Condition / Medicine | C3: Intern 1 | D3: Intern 2 | E3: Intern 3 | F3: Intern 4 | H3: Condition / Medicine | I3: Intern 1 | J3: Intern 2 | K3: Intern 3
B4: Depression | C4: Frances | D4: Mo (Omar) | E4: Kat | F4: Phylicia | H4: Depression | M4: 1 | N4: Amalnath | P4: Amalnath Sadanandan
B5: Schizophrenia | C5: Jay | D5: Niyati | E5: Philippe | F5: Yi Rou | H5: Schizophrenia | M5: 2 | N5: Angel | P5: Angel Paul
B6: Bipolar Disorder | C6: Ji Hee | D6: Sai | E6: Sam | F6: Ehsan | H6: Bipolar Disorder | M6: 3 | N6: Ann | P6: Ann (Lorieall) Sureta
B7: ADHD | C7: Joanne | D7: Laurence | E7: Xin Pei | F7: - | H7: ADHD | M7: 4 | N7: Anumol | P7: Anumol Paulose
B8: Insomnia | C8: Leah | D8: Jessie | E8: Patty | F8: - | H8: Insomnia | M8: 5 | N8: Ayesha | P8: Ayesha Tabinda
B9: Gout | C9: Aziza | D9: Rica | E9: Amrutha | F9: - | H9: Gout | M9: 6 | N9: Chinwe | P9: Chinwe Stella Melifonqu
B10: Sprains and Strains + Diclofenac 25mg | C10: Jasmin | D10: Sadaf | E10: Hana | F10: - | H10: Sprains and Strains + Diclofenac 25mg | M10: 7 | N10: Farhana | P10: Farhana Naureen Anwar
B11: Rheumatoid Arthritis | C11: Marvelous | D11: Yuvraj | E11: Mukta | F11: - | H11: Rheumatoid Arthritis | M11: 8 | N11: Hanna | P11: Hanna Simon
B12: Osteoarthritis + Panadol Osteo | C12: Mingxin | D12: Rekha | E12: Nidhi | F12: - | H12: Osteoarthritis + Panadol Osteo | M12: 9 | N12: Janet | P12: Janet Jomon
M13: 10 | N13: Kisal | P13: Kisal Lewanjith Bogahakumbura Bogahakumbure
B14: Regional | H14: Tauranga | M14: 11 | N14: Michael | P14: Michael Mories
B15: Condition / Medicine | C15: Intern 1 | D15: Intern 2 | E15: Intern 3 | F15: Intern 4 | H15: Condition / Medicine | I15: Intern 1 | J15: Intern 2 | K15: Intern 3 | M15: 12 | N15: Mo | P15: Mohammed Galaleldin Elsayed Omar
B16: Depression | C16: Alyssa | D16: Abhishek | E16: Amalnath | F16: Janet | H16: Depression | M16: 13 | N16: Nehal | P16: Nehalben Narendrabhai Patel
B17: Schizophrenia | C17: Crystal | D17: Gyan | E17: Angel | F17: Kamran | H17: Schizophrenia | M17: 14 | N17: Rasheema | P17: Rasheema Savad
B18: Bipolar Disorder | C18: Greeshma | D18: Jenny | E18: Ann (Lorieall) | F18: Kisal | H18: Bipolar Disorder | M18: 15 | N18: Sharu | P18: Sharulatha Velmurugan
B19: ADHD | C19: Fylgia | D19: Rio | E19: Annissa | F19: Michael | H19: ADHD | M19: 16 | N19: Victor | P19: Victor Onyirioha
B20: Insomnia | C20: Ella | D20: Zeh Yee | E20: Anumol | F20: Nehalben | H20: Insomnia | M20: 17 | N20: Yakesh | P20: Yakeshkumar Pravinchandra Modi
B21: Gout | C21: Hardik | D21: Zhi Qi | E21: Ayesha | F21: Rahul | H21: Gout
B22: Sprains and Strains + Diclofenac 25mg | C22: Howard | D22: Sonia | E22: Chinwe | F22: Rasheema | H22: Sprains and Strains + Diclofenac 25mg
B23: Rheumatoid Arthritis | C23: Wonje | D23: Stacey | E23: Farhana | F23: Savitha | H23: Rheumatoid Arthritis
B24: Osteoarthritis + Panadol Osteo | C24: Yakeshkumar | D24: Victor | E24: Hanna | F24: Sharulatha | H24: Osteoarthritis + Panadol Osteo
B26: Hamilton | H26: Wellington
B27: Condition / Medicine | C27: Intern 1 | D27: Intern 2 | E27: Intern 3 | H27: Condition / Medicine | I27: Intern 1 | J27: Intern 2 | K27: Intern 3
B28: Depression | H28: Depression
B29: Schizophrenia | H29: Schizophrenia
B30: Bipolar Disorder | H30: Bipolar Disorder
B31: ADHD | H31: ADHD
B32: Insomnia | H32: Insomnia
B33: Gout | H33: Gout
B34: Sprains and Strains + Diclofenac 25mg | H34: Sprains and Strains + Diclofenac 25mg
B35: Rheumatoid Arthritis | H35: Rheumatoid Arthritis
B36: Osteoarthritis + Panadol Osteo | H36: Osteoarthritis + Panadol Osteo
B39: NRE Frances Diana Encarnacion | C39: NRE Mohammed Galaleldin Elsayed Omar | D39: NRE Kathleen Gomez | E39: DOM Aziza Shawudun
B40: DOM Jay (Zhijian) Wang | C40: NRE Niyati Shah | D40: NRE Philippe Koo | E40: NRE Jasmin Jomon | G40: NRE Amrutha Chelath
B41: DOM Ji Hee Jeong | C41: DOM Sai Chakrahari | D41: DOM Samuel (Dong Yeon) Jung | E41: DOM Marvelous (Moradeke) Adesina | G41: NRE Hana Nazim | I41: DOM Annissa Izham | K41: NRE Nehalben Narendrabhai Patel
B42: DOM Joanne Cao | C42: NRE Laurence Richard Gaboy | D42: DOM Xin Pei Tay | E42: DOM Mingxin Mei | G42: RTP Mukta Batra | I42: NRE Farhana Naureen Anwar | K42: NRE Abhishek Sharma | M42: NRE Angel Paul
B43: NRE Leah Bunales | C43: DOM Jessie (Jiyun) Jung | D43: NRE Patty Santos | E43: NRE Rica Mae Estillore | G43: NRE Nidhi Jariwala | I43: NRE Kisal Lewanjith Bogahakumbura Bogahakumbure | K43: NRE Ann (Lorieall) Sureta | M43: NRE Anumol Paulose
I44: NRE Rasheema Savad | K44: NRE Chinwe Stella Nelifonqu | M44: NRE Ayesha Tabinda
...

Sheet Apr Workshop Allocations
B2: Auckland | F2: Online
B3: Condition | C3: Timeframe | D3: Presenter(s) | F3: Condition | G3: Timeframe | H3: Study Group | J3: Online | L3: Online
B4: Headaches: Tension vs Migraine vs Sinus vs Medication Overuse (Please include Prochlorperazine and Sumatriptan) | C4: 15min total | D4: Frances Encarnacion, Jay (Zhijian) Wang, Ji Hee Jeong, Joanne Cao, Leah Bunales | F4: Headaches: Tension vs Migraine vs Sinus vs Medication Overuse (Please include Prochlorperazine and Sumatriptan) | G4: 15min total | H4: Amalnath Sadanandan, Ayesha Tabinda | J4: NRE Amalnath Sadanandan | L4: NRE Farhana Naureen Anwar
B5: Common Infections: Cough vs Cold vs Flu vs COVID (Please also cover Pseudoephedrine and Tamiflu) | C5: 15min total | D5: Phylicia Chong, Rekha Paily, Sadaf Ahmad, Yi Rou Lim, Yuvraj Chaudary Kewal | F5: Common Infections: Cough vs Cold vs Flu vs COVID (Please also cover Pseudoephedrine and Tamiflu) | G5: 15min total | H5: Chinwe Melifonqu | J5: NRE Ayesha Tabinda | L5: NRE Kisal Lewanjith Bogahakumbura Bogahakumbure
B6: Sore Throats: Viral vs Bacterial (Please include Strep Throat and Rheumatic Fever) | C6: 10min total | D6: Mohammed Omar, Niyati Shah, Sai Chakrahari, Laurence Gaboy, Jessie Jung | F6: Sore Throats: Viral vs Bacterial (Please include Strep Throat and Rheumatic Fever) | G6: 10min total | H6: Hanna Simon | J6: NRE Chinwe Stella Melifonqu | L6: NRE Rasheema Savad
B7: Measles (include Public Health Considerations and info on Vaccinations) | C7: 10min total | D7: Kathleen Gomez, Philippe Koo, Samuel Jung, Xin Pei Tay, Paddy Santos | F7: Measles (include Public Health Considerations and info on Vaccinations) | G7: 10min total | H7: Yakeshkumar Modi, Rasheema Savad | J7: NRE Kamran Ghnbari | L7: NRE Yakeshkumar Pravinchandra Modi
B8: Whooping Cough (include Public Health Considerations and info on Vaccinations) | C8: 10min total | D8: Amrutha Chelath, Hana Nazim, Mukta Batra, Nidhi Jariwala | F8: Whooping Cough (include Public Health Considerations and info on Vaccinations) | G8: 10min total | H8: Kisal Bogahakumbure, Farhana Anwar | J8: NRE Zhi Qi Wong | L8: NRE Hanna Simon
B9: Meningitis (include Public Health Considerations and info on Vaccinations) | C9: 10min total | D9: Aziza Shawudun, Jasmin Jomon, Marvelous Adesina, Mingxin Mei, Rica Mae Estillore
J10: NRE Frances Diana Encarnacion | K10: NRE Mohammed Galaleldin Elsayed Omar | L10: NRE Kathleen Gomez | M10: DOM Aziza Shawudun | N10: NRE Amrutha Chelath
J11: DOM Jay (Zhijian) Wang | K11: NRE Niyati Shah | L11: NRE Philippe Koo | M11: NRE Jasmin Jomon | N11: NRE Hana Nazim
B12: Christchurch | F12: Tauranga | J12: DOM Ji Hee Jeong | K12: DOM Sai Chakrahari | L12: DOM Samuel (Dong Yeon) Jung | M12: DOM Marvelous (Moradeke) Adesina | N12: RTP Mukta Batra
B13: Condition | C13: Timeframe | D13: Presenter(s) | F13: Condition | G13: Timeframe | H13: Presenter(s) | J13: DOM Joanne Cao | K13: NRE Richard Laurence | L13: DOM Xin Pei Tay | M13: DOM Mingxin Mei | N13: NRE Nidhi Jariwala
B14: Headaches: Tension vs Migraine vs Sinus vs Medication Overuse (Please include Prochlorperazine and Sumatriptan) | C14: 15min total | D14: Alyssa Andres, Crystal Yi | F14: Headaches: Tension vs Migraine vs Sinus vs Medication Overuse (Please include Prochlorperazine and Sumatriptan) | G14: 15min total | H14: Angel Paul, Anumol Paulose | J14: NRE Leah Bunales | K14: DOM Jessie (Jiyun) Jung | L14: NRE Paddy Santos | M14: NRE Rica Mae Estillore
B15: Common Infections: Cough vs Cold vs Flu vs COVID (Please also cover Pseudoephedrine and Tamiflu) | C15: 15min total | D15: Greeshma Raj, Fylgia Romero | F15: Common Infections: Cough vs Cold vs Flu vs COVID (Please also cover Pseudoephedrine and Tamiflu) | G15: 15min total | H15: Ann (Lorieall) Sureta, Janet Jomon
B16: Sore Throats: Viral vs Bacterial (Please include Strep Throat and Rheumatic Fever) | C16: 10min total | D16: Ella Wang, Hardik Ahuja | F16: Sore Throats: Viral vs Bacterial (Please include Strep Throat and Rheumatic Fever) | G16: 10min total | H16: Michael Mories, Sharulatha Velmurugan | J16: DOM Phylicia Chong
B17: Measles (include Public Health Considerations and info on Vaccinations) | C17: 10min total | D17: Howard Liu | F17: Measles (include Public Health Considerations and info on Vaccinations) | G17: 10min total | H17: Nehalben Patel | J17: NRE Rekha Paily
B18: Whooping Cough (include Public Health Considerations and info on Vaccinations) | C18: 10min total | D18: Wonje Lee | F18: Whooping Cough (include Public Health Considerations and info on Vaccinations) | G18: 10min total | H18: Victor Onyirioha | J18: DOM Sadaf Ahmad
J19: DOM Yi Rou Lim
J20: DOM Yuvraj Chaudary Kewal
B22: Hamilton | F22: Wellington
B23: Condition | C23: Timeframe | D23: Presenter(s) | F23: Condition | G23: Timeframe | H23: Presenter(s)
B24: Headaches: Tension vs Migraine vs Sinus vs Medication Overuse (Please include Prochlorperazine and Sumatriptan) | C24: 15min total | D24: Gyan Ilarde Lumo | F24: Headaches: Tension vs Migraine vs Sinus vs Medication Overuse (Please include Prochlorperazine and Sumatriptan) | G24: 15min total | H24: Annissa Izham
B25: Common Infections: Cough vs Cold vs Flu vs COVID (Please also cover Pseudoephedrine and Tamiflu) | C25: 15min total | D25: Abhishek Sharma, Zhi Qi Wong | F25: Common Infections: Cough vs Cold vs Flu vs COVID (Please also cover Pseudoephedrine and Tamiflu) | G25: 15min total | H25: Rahul Kumar Pandey
B26: Sore Throats: Viral vs Bacterial (Please include Strep Throat and Rheumatic Fever) | C26: 10min total | D26: Rio Marielle Booc, Kamran Ghanbari | F26: Sore Throats: Viral vs Bacterial (Please include Strep Throat and Rheumatic Fever) | G26: 10min total | H26: Savitha Nair
B27: Measles (include Public Health Considerations and info on Vaccinations) | C27: 10min total | D27: Zeh Yee Yau | F27: Measles (include Public Health Considerations and info on Vaccinations) | G27: 10min total | H27: Sonia Alex
B28: Whooping Cough (include Public Health Considerations and info on Vaccinations) | C28: 10min total | D28: Jenny Yan | F28: Whooping Cough (include Public Health Considerations and info on Vaccinations) | G28: 10min total | H28: Stacey Lee
B31: Tauranga | D31: Wellington | F31: Hamilton | H31: Christchurch
B32: NRE Angel Paul | D32: DOM Annissa Izham | F32: NRE Abhishek Sharma | H32: DOM Ella (Jinghan) Wang
B33: NRE Ann (Lorieall) Sureta | D33: NRE Rahul Kumar Pandey | F33: DOM Gyan (Roger) Ilarde Lumo | H33: NRE Hardik Ahuja
B34: NRE Anumol Paulose | D34: NRE Savitha Venukuttan Nair | F34: NRE Jenny (Zhixin) Yan | H34: DOM Howard Liu
B35: NRE Janet Jomon | D35: NRE Sonia Alex | F35: DOM Rio Marielle Booc | H35: DOM Wonje Lee
B36: NRE Michael Mories | D36: DOM Stacey Ji Soo Lee | F36: DOM Zeh Yee Yau
B37: NRE Nehalben Narendrabhai Patel | H37: Christchurch
B38: NRE Sharulatha Velmurugan | H38: NRE Alyssa Andres
B39: NRE Victor Onyirioha | H39: DOM Crystal (Jooeun) Yi
H40: NRE Greeshma Raj
H41: DOM Fylgia Romero
B58: 2860.96 | C58: =B58*1.15 -> 3290.104 | D58: =C58*1.0325 -> 3397.0324
B59: 2860.96 | C59: =B59*1.0325 -> 2953.9412 | D59: =C59*1.15 -> 3397.0324
C60: =3.25+15 -> 18.25 | D60: =B59*1.1825 -> 3383.0852
...

Sheet Mar Workshop Allocations
B2: Auckland | F2: Online
B3: Condition | C3: Timeframe | D3: Presenter(s) | F3: Condition | G3: Timeframe | H3: Study Group | J3: Online | L3: Online
B4: Acne and Rosacea | C4: 5min each, ~10min total | D4: Frances Encarnacion, Jay (Zhijian) Wang, Ji Hee Jeong, Joanne Cao, Leah Bunales | F4: Acne and Rosacea | G4: 5min each, ~10min total | H4: Amalnath Sadanandan, Ayesha Tabinda | J4: NRE Amalnath Sadanandan | L4: NRE Farhana Naureen Anwar
B5: Tinea Infections - Ringworm, Jock Itch, Athletes Foot, Nail Conditions | C5: 15min total | D5: Phylicia Chong, Rekha Paily, Sadaf Ahmad, Yi Rou Lim, Yuvraj Chaudary Kewal | F5: Tinea Infections - Ringworm, Jock Itch, Athletes Foot, Nail Conditions | G5: 15min total | H5: Chinwe Melifonqu, Zhi Qi Wong | J5: NRE Ayesha Tabinda | L5: NRE Kisal Lewanjith Bogahakumbura Bogahakumbure
B6: Parasitic Infections - Scabies, Worms, Headlice | C6: 5min each, ~15min total | D6: Mohammed Omar, Niyati Shah, Sai Chakrahari, Richard Laurence, Jessie Jung | F6: Parasitic Infections - Scabies, Worms, Headlice | G6: 5min each, ~15min total | H6: Hanna Simon | J6: NRE Chinwe Stella Melifonqu | L6: NRE Rasheema Savad
B7: Seborrheic Dermatitis and Dandruff | C7: 5min each, ~10min total | D7: Kathleen Gomez, Philppe Koo, Samuel Jung, Xin Pei Tay, Paddy Santos | F7: Seborrheic Dermatitis and Dandruff | G7: 5min each, ~10min total | H7: Yakeshkumar Modi, Rasheema Savad | J7: NRE Kamran Ghnbari | L7: NRE Yakeshkumar Pravinchandra Modi
B8: Hives, Bites, Stings | C8: 10min total | D8: Amrutha Chelath, Hana Nazim, Mukta Batra, Nidhi Jariwala | F8: Psoriasis + Impetigo | G8: 5min each, ~10min total | H8: Kisal Bogahakumbure, Farhana Anwar | J8: NRE Zhi Qi Wong | L8: NRE Hanna Simon
B9: Psoriasis + Impetigo | C9: 5min each, ~10min total | D9: Aziza Shawudun, Jasmin Jomon, Marvelous Adesina, Mingxin Mei, Rica Mae Estillore
J10: NRE Frances Diana Encarnacion | K10: NRE Mohammed Galaleldin Elsayed Omar | L10: NRE Kathleen Gomez | M10: DOM Aziza Shawudun | N10: NRE Amrutha Chelath
F11: Tauranga | J11: DOM Jay (Zhijian) Wang | K11: NRE Niyati Shah | L11: NRE Philppe Koo | M11: NRE Jasmin Jomon | N11: NRE Hana Nazim
B12: Christchurch | F12: Condition | G12: Timeframe | H12: Presenter(s) | J12: DOM Ji Hee Jeong | K12: DOM Sai Chakrahari | L12: DOM Samuel (Dong Yeon) Jung | M12: DOM Marvelous (Moradeke) Adesina | N12: RTP Mukta Batra
B13: Condition | C13: Timeframe | D13: Presenter(s) | F13: Acne and Rosacea | G13: 5min each, ~10min total | H13: Angel Paul, Anumol Paulose | J13: DOM Joanne Cao | K13: NRE Richard Laurence | L13: DOM Xin Pei Tay | M13: DOM Mingxin Mei | N13: NRE Nidhi Jariwala
B14: Acne and Rosacea | C14: 5min each, ~10min total | D14: Alyssa Andres, Crystal Yi | F14: Tinea Infections - Ringworm, Jock Itch, Athletes Foot, Nail Conditions | G14: 15min total | H14: Ann (Lorieall) Sureta, Janet Jomon | J14: NRE Leah Bunales | K14: DOM Jessie (Jiyun) Jung | L14: NRE Paddy Santos | M14: NRE Rica Mae Estillore
B15: Tinea Infections - Ringworm, Jock Itch, Athletes Foot, Nail Conditions | C15: 15min total | D15: Greeshma Raj, Fylgia Romero | F15: Parasitic Infections - Scabies, Worms, Headlice | G15: 5min each, ~15min total | H15: Michael Mories, Sharulatha Velmurugan
B16: Parasitic Infections - Scabies, Worms, Headlice | C16: 5min each, ~15min total | D16: Ella Wang, Hardik Ahuja | F16: Seborrheic Dermatitis and Dandruff | G16: 5min each, ~10min total | H16: Nehalben Patel | J16: DOM Phylicia Chong
B17: Seborrheic Dermatitis and Dandruff | C17: 5min each, ~10min total | D17: Howard Liu | F17: Psoriasis + Impetigo | G17: 5min each, ~10min total | H17: Victor Onyirioha | J17: NRE Rekha Paily
B18: Psoriasis + Impetigo | C18: 5min each, ~10min total | D18: Wonje Lee | J18: DOM Sadaf Ahmad
F19: Wellington | J19: DOM Yi Rou Lim
B20: Hamilton | F20: Condition | G20: Timeframe | H20: Presenter(s) | J20: DOM Yuvraj Chaudary Kewal
B21: Condition | C21: Timeframe | D21: Presenter(s) | F21: Acne and Rosacea | G21: 5min each, ~10min total | H21: Annissa Izham
B22: Acne and Rosacea | C22: 5min each, ~10min total | D22: Gyan Ilarde Lumo | F22: Tinea Infections - Ringworm, Jock Itch, Athletes Foot, Nail Conditions | G22: 15min total | H22: Rahul Kumar Pandey
B23: Tinea Infections - Ringworm, Jock Itch, Athletes Foot, Nail Conditions | C23: 15min total | D23: Abhishek Sharma | F23: Parasitic Infections - Scabies, Worms, Headlice | G23: 5min each, ~15min total | H23: Savitha Nair
B24: Parasitic Infections - Scabies, Worms, Headlice | C24: 5min each, ~15min total | D24: Rio Marielle Booc, Kamran Ghanbari | F24: Seborrheic Dermatitis and Dandruff | G24: 5min each, ~10min total | H24: Sonia Alex
B25: Seborrheic Dermatitis and Dandruff | C25: 5min each, ~10min total | D25: Zeh Yee Yau | F25: Psoriasis + Impetigo | G25: 5min each, ~10min total | H25: Stacey Lee
B26: Psoriasis + Impetigo | C26: 5min each, ~10min total | D26: Jenny Yan
F28: Hamilton | G28: Christchurch | H28: Christchurch
B29: Tauranga | D29: Wellington | F29: NRE Abhishek Sharma | G29: NRE Alyssa Andres | H29: DOM Ella (Jinghan) Wang
B30: NRE Angel Paul | D30: DOM Annissa Izham | F30: DOM Gyan (Roger) Ilarde Lumo | G30: DOM Crystal (Jooeun) Yi | H30: NRE Hardik Ahuja
B31: NRE Ann (Lorieall) Sureta | D31: NRE Rahul Kumar Pandey | F31: NRE Jenny (Zhixin) Yan | G31: NRE Greeshma Raj | H31: DOM Howard Liu
B32: NRE Anumol Paulose | D32: NRE Savitha Venukuttan Nair | F32: DOM Rio Marielle Booc | G32: DOM Fylgia Romero | H32: DOM Wonje Lee
B33: NRE Janet Jomon | D33: NRE Sonia Alex | F33: DOM Zeh Yee Yau
B34: NRE Michael Mories | D34: DOM Stacey Ji Soo Lee
B35: NRE Nehalben Narendrabhai Patel
B36: NRE Sharulatha Velmurugan
B37: NRE Victor Onyirioha

Sheet 2025 Topics Covered
B2: OTC | G2: POM | L2: Therapeutics
B3: Month | C3: Topic | D3: Covered in: | E3: Details | G3: Month | H3: Topic | I3: Covered in: | J3: Details: | L3: Month | M3: Topic | N3: Covered in: | O3: Details:
B4: February | C4: Hayfever and allergies | D4: EOM Checkpoint | E4: Case: Request for Clear Eyes and Phenergan | G4: February | H4: Adrenaline | L4: February | M4: Inflammatory Bowel Disease | N4: Focus Group | O4: Case: Pentasa Suppositories in Ulcerative proctitis
B5: February | C5: Indigestion & Heartburn | D5: EOM Checkpoint | E5: Case: Pregnant woman on iron suspects cancer | G5: February | H5: Sedating Antihistamines | I5: Focus Group | J5: Case: Mother's request for Promethazine for cold/flu symptoms + sleep on flight | L5: February | M5: Irritable Bowel Syndrome | N5: Focus Group | O5: Case: Denial of Buscopan (Anticholinergic interaction)
B6: February | C6: Constipation | D6: EOM Checkpoint | E6: Case: Pregnant woman on iron suspects cancer | G6: February | H6: Gastrosoothe | I6: Focus Group | J6: Case: Denial of Buscopan (Anticholinergic interaction) | L6: February | M6: Constipation | N6: EOM Checkpoint | O6: Case: Pregnant woman on iron suspects cancer
B7: February | C7: Diarrhoea & Vomiting | D7: EOM Checkpoint | E7: Case: Request for Loperamide for a 4-year old | G7: February | H7: Bowel cleansing agents | I7: Research Template | L7: February | M7: Diarrhoea | N7: EOM Checkpoint | O7: Case: Request for Loperamide for a 4-year old
B8: February | C8: Haemorrhoids | D8: EOM Checkpoint | E8: Extra for experts: Haemorroid treatment in pregnancy | G8: February | H8: Rectogesic | I8: Research Template | L8: February | M8: Nausea and vomiting | N8: Research Template
B9: March | C9: Dry skin | D9: Presentation | E9: Intern | G9: March | H9: Vaginal thrush | I9: EOM Checkpoint | J9: Case: Vaginal Thrush (Uncontrolled T2DM but blamed on Empagliflozin) | L9: February | M9: GERD | N9: EOM Checkpoint | O9: Case: Pregnant woman on iron suspects cancer
B10: March | C10: Dermatitis, Eczema | D10: Focus Group | E10: Case: Request for Calamine (Childhood Eczema) | G10: March | H10: Hydrocortisone 1% | I10: Focus Group | J10: Childhood Eczema | L10: February | M10: Haemorrhoids | N10: EOM Checkpoint | O10: Extra for experts: Haemorroid treatment in pregnancy
B11: March | C11: Dermatitis, Eczema | D11: Presentation | E11: Intern | G11: March | H11: Clobetasone | L11: February | M11: Anal fissures | N11: Research Template
B12: March | C12: Tinea (Skin, foot, nail) | D12: Focus Group | E12: Case: Athelte's Foot into Fungal Nail Infection | G12: March | H12: Micreme H, Canesten Plus | L12: February | M12: Antiemetics | N12: Research Template
B13: March | C13: Tinea (Skin, foot, nail) | D13: Presentation | E13: Intern | G13: April | H13: Vaginal thrush | I13: Focus Group | J13: Case: Wants Fluconazole but they are on Colchicine (Interaction) (KEN) | L13: February | M13: Heart Failure | N13: Focus Group | O13: Case: Changing from ACE-I to Entresto
B14: March | C14: Nappy Rash | D14: EOM Checkpoint | E14: ?with Micreme H? | G14: April | H14: Adapalene | I14: Focus Group | J14: Case: Adapalene for Acne (KEN Apr 2024 EOM) | L14: February | M14: Angina | N14: Focus Group | O14: Case: Step up therapy; Duride NEW
B15: March | C15: Nappy Rash | D15: Presentation | E15: Intern | G15: April | H15: Calcipotriol | I15: Focus Group | J15: Case: Calcipotriol for Psoriasis - patient wants to initiate but taking VitD 1/month | L15: February | M15: Arrhythmias | N15: Focus Group | O15: Case: Switching from Warfarin to Dabigatrin
B16: March | C16: Psoriasis | D16: Presentation | E16: Intern | G16: April | H16: Adrenaline | I16: EOM Checkpoint | J16: Case: Hives but requests epipen believing that's the solution | L16: February | M16: Hypertension | N16: Research Template
B17: March | C17: Hives, Bites & stings | D17: Presentation | E17: Intern | G17: May | H17: Pseudoephedrine | I17: Presentation | J17: Intern | L17: February | M17: Hyperlipidemia | N17: Research Template
B18: March | C18: Scabies | D18: Focus Group | E18: Case: Mother mistakes Scabies as Eczema | G18: May | H18: Pseudoephedrine | I18: Focus Group | J18: Case: Patient thinks it's migraine, it's sinus (xPseudo - HF) | L18: March | M18: Type 1 Diabetes | N18: Case for Self Study | O18: Case: Insulin and T1DM Counselling (Child)
B19: March | C19: Scabies | D19: Presentation | E19: Intern | G19: May | H19: Prochlorperazine | I19: Presentation | J19: Intern | L19: March | M19: Type 2 Diabetes | N19: Focus Group | O19: Case: Metformin GI Side Effects
B20: March | C20: Worms | D20: Case for Self Study | E20: Case: Family with Worms | G20: May | H20: Prochlorperazine | I20: Focus Group | J20: Case: Supplying one, initial diagnosis, clear hx and sx - however interaction | L20: March | M20: Type 2 Diabetes | N20: EOM Checkpoint | O20: Case: Vaginal Thrush (Uncontrolled T2DM but blamed on Empagliflozin)
B21: March | C21: Worms | D21: Presentation | E21: Intern | G21: May | H21: Cyclizine | I21: Focus Group | J21: Case: Cyclizine (Patient has bad food poisoning) | L21: March | M21: Hypothyroidism | N21: Focus Group | O21: Case: New Levothyroxine Counselling
B22: March | C22: Headlice | D22: Case for Self Study | E22: Case: Wants shampoo for dandruff but has headlice | G22: May | H22: Sumatriptan | I22: Focus Group | J22: Case: Supplying one, initial diagnosis, clear hx and sx - however interaction | L22: March | M22: Hyperthyroidism | N22: EOM Checkpoint | O22: Case: New Carbimazole Counselling
B23: March | C23: Headlice | D23: Presentation | E23: Intern | G23: May | H23: Sumatriptan | I23: Presentation | J23: Intern | L23: April | M23: Gout | N23: Focus Group | O23: Case: New Allopurinol Counselling (NEW, uptitrate, allergic reaction)
B24: March | C24: Acne | D24: Presentation | E24: Intern | G24: May | H24: Dextromethorphan | I24: Self Study | J24: No product available at this time | L24: April | M24: Gout | O24: Case: Voltaren but T2DM (just on Metformin) and BP meds
B25: March | C25: Rosacea | D25: Presentation | E25: Intern | G25: May | H25: Oseltamivir | I25: Presentation | J25: Intern | L25: April | M25: Sprains and Strains | N25: Focus Group | O25: Case: ParaCodeine & Home, can they use? (No, NSAID + PRICE)
B26: March | C26: Impetigo | D26: Presentation | E26: Intern | G26: May | H26: Oseltamivir | I26: EOM Checkpoint | J26: POM Purchase in Advance | L26: April | M26: Rheumatoid Arthritis | N26: Focus Group | O26: Case: New Methotrexate Counselling (KEN)
B27: March | C27: Dandruff and Cradle Cap | D27: Presentation | E27: Intern | G27: June | H27: Diclofenac 25mg | I27: Focus Group | J27: Voltaren Triple Whammy - Ramipril + Indapamide collected elsewhere (Claude done) | L27: April | M27: Osteoarthritis | N27: Focus Group | O27: Case: Voltaren but interaction with Lithium
B28: April | C28: Seborrheic Dermatitis | D28: Focus Group | E28: Fluconazole for scalp but should do Sebizole+Cream | G28: June | H28: Panadol Osteo | I28: Self Study | J28: Commonly dispensed and covered in-store | L28: April | M28: Muscular aches, pains, and tightness | N28: Research Template
B29: April | C29: Chicken Pox and Shingles | D29: Focus Group | E29: Case: Amitriptyline and Valaciclovir (KEN) | G29: June | H29: Naproxen | I29: Focus Group | J29: POM for Primary Period Pain (Claude done) | L29: May | M29: Measles | N29: Presentation | O29: Intern
B30: April | C30: Cuts and Grazes | D30: EOM Checkpoint | E30: Case: Bleeding wound from an Elderly Patient | G30: July | H30: Chlorsig | I30: Focus Group | J30: Case: Allergy eyes but is bacterial, supply chlorsig | L30: May | M30: Whooping Cough | N30: Presentation | O30: Intern
B31: April | C31: Cuts and Grazes | D31: Research Template | E31: Presentation from Smith & Nephew | G31: August | H31: Neutrafluor | I31: Presentation | J31: Intern | L31: May | M31: Meningitis | N31: Presentation | O31: Intern
B32: April | C32: Puncture & Surgical Wounds | D32: EOM Checkpoint | E32: Case: Nail puncture (Tetanus Prone Wound) | G32: August | H32: Melatonin | I32: Presentation | J32: Intern | L32: May | M32: Palliative Care | N32: Presentation | O32: Guest Presentation - Hospice
B33: April | C33: Puncture & Surgical Wounds | D33: Research Template | G33: August | H33: Melatonin | I33: Focus Group | J33: Case: Simple primary, can supply. Give questionnaire | L33: May | M33: Med Int - H. Pylori + Statin | N33: Focus Group | O33: H. Pylori Tx (Clarithromycin), Statin dispensed 1.5 months ago in Hx
B34: April | C34: Blisters & Ulcers | D34: Research Template | G34: August | H34: Nystatin and Miconazole | I34: Presentation | J34: Intern | L34: May | M34: Meningitis | N34: Focus Group | O34: KEN
B35: April | C35: Burns & Scarring | D35: EOM Checkpoint | E35: Case: Oil Burn | G35: August | H35: Triamcinolone | I35: Presentation | J35: Intern | L35: May | M35: Nausea and Vomiting | N35: Focus Group | O35: Nausea Management Table Breakdown
B36: April | C36: Burns & Scarring | D36: Research Template | E36: Presentation from Smith & Nephew | G36: August | H36: Diphenhydramine & Doxylamine | I36: Presentation | J36: Intern | L36: June | M36: Depression | N36: EOM Checkpoint | O36: Ken: Switching (Fluox to Venlafaxine) (Claude done)
B37: May | C37: Pain and Fever (Child vs Adult) | D37: Presentation | E37: Intern | G37: August | H37: Diphenhydramine & Doxylamine | I37: Focus Group | J37: Case: Unisom, recently started on ritalin, losing sleep. Secondary. Someone sold before | L37: June | M37: Schizophrenia | N37: Focus Group | O37: Olanzapine - Weight gain (asking for supplement) Ange has
B38: May | C38: Pain (Adult) | D38: Focus Group | E38: Case: Pain Ladder (Panadol, Ibuprofen, Tramadol, Laxsol) | G38: August | H38: Famciclovir | I38: Presentation | J38: Intern | L38: June | M38: Bipolar disorder | N38: Focus Group | O38: Lithium counselling. Sporty - Ibuprofen + Electrolytes (Panadol+Counselling)
B39: May | C39: Headaches (Tension, Migraine, Sinus, Med Overuse) | D39: Presentation | E39: Intern | G39: August | H39: Famciclovir | I39: Focus Group | J39: Case: 3rd trimester, cold sore now, coutners with wanting as backpocket (not safe BF) | L39: June | M39: ADHD | N39: Focus Group | O39: Concerned mother - new diagnosis. Stigma. Long Term SE. Ritalin IM. Queries Melatonin
B40: May | C40: Headaches (Sinus) | D40: Focus Group | E40: Case: Patient thinks it's migraine, it's sinus (xPseudo - HF) | L40: June | M40: Insomnia | N40: Focus Group | O40: 56y/o on Fluoxetine. Melatonin X Promethazine X REM Sleep/Tart Cherry/Magnesium -> See Dr for Med
B41: May | C41: Coughs, Colds, Flu, COVID | D41: Presentation | E41: Intern | L41: June | M41: Pregnancy and Breastfeeding | N41: Presentation | O41: Ken & Ange
...
